Workbook
Name Datenschnitt_Übernahme__in_S_4_geplant: #N/A

Sheet Z-Programme
A1: Z-Programm R/3 (insgesamt 654) | B1: vorhanden EQA | C1: Übernahme in S/4 geplant | D1: USR CALM | E1: Welle 1 | F1: Welle 2 | G1: Welle 3 ff | H1: Coding Zahlwege | I1: Klärung durch | J1: Beschreibung
A2: Z_CLEAN_EVTTAB | B2: Nein | C2: Nein | J2: Hilfsprogramm zur Bereinigung Inkonsistenzen in Jobtabelle BTCEVTJOB
A3: Z_IDOC_STATUS_SET | B3: Nein | C3: Ja | F3: Nein | G3: Ja | J3: Idoc Status auf erledigt setzen (nur BuKrs 1000)
A4: Z_INFO_PRICING_SERVICES_USER | B4: Nein | C4: Nein | J4: Z_INFO_PRICING_SERVICES_USER lt. SAP Hinweis 1786263
A5: Z_REPAIR_ADRNR_1 | B5: Nein | C5: Nein | J5: Reparatur der Adressinkonsistenz in Tabelle VBPA und KNA1
A6: Z_SAPMZSWA | B6: Nein | C6: Ja | F6: Nein | G6: Ja | J6: Programm SAPMZSWA - Batterieservice
A7: Z_SAPMZSWA_MENUE | B7: Nein | C7: Ja | F7: Nein | G7: Ja | J7: Menü Batterieservice
A8: Z_SAPMZSWAT | B8: Nein | C8: Ja | F8: Nein | G8: Ja | J8: Modulpool: Elektronisches Bezahlen SWA-Terminal (Straßenwacht)
A9: Z0SAP_12 | B9: Nein | C9: Nein | J9: Datendatei-View: Geplante Abschreibungen auf Anlagen
A10: ZAA_ANLAGENTR_COPY_LANGTEXT | B10: Nein | C10: Nein | J10: Anlagentransfer Langtexte kopieren
A11: ZAA_ANLAGENTRANSFER | B11: Nein | C11: Nein | J11: Anlagentransfer
A12: ZAA_CO_KONTIERUNG | B12: Nein | C12: Nein | J12: Änderung von Innenaufträgen/Kostenstellen in Anlagen
A13: ZAA_INVE01 | B13: Nein | C13: Nein | J13: Inventurliste nach Anlagennummern / Anlagentext
A14: ZAA_INVE06 | B14: Nein | C14: Nein | J14: Inventurliste nach Anlagennummern / Anlagentext
A15: ZAA_INVE07 | B15: Nein | C15: Nein | J15: Inventurliste nach Kostenrechnungsobjekten
A16: ZAA_MASS_DOWN | B16: Nein | C16: Nein | D16: DEV-002 | J16: Anlagenstamm Massenänderung: Download
A17: ZAA_MASS_UP | B17: Nein | C17: Nein | D17: DEV-002 | J17: Massenänderung Anlagenstamm: Upload CSV-Datei
A18: ZAA_RAHIST01 | B18: Nein | C18: Nein | J18: Anlagenhistorie
A19: ZAA_RAPOST2010 | B19: Nein | C19: Nein | J19: Buchen der Abschreibungen
A20: ZAA_STAMMDAT_ALV | B20: Nein | C20: Nein | D20: DEV-002 | J20: Stammdaten-Auswertung ALV-Liste ( mehrzeilig )
A21: ZACAC_DATA_TRANSFER | B21: Ja | C21: Ja | D21: DEV-150 | E21: Ja | J21: Übernahme von Debitoren-/Kreditorenrechnungen in die Accrual Engine
A22: ZACAC_DSITEMS | B22: Nein | C22: Nein | J22: Anzeigen von Abgrenzungsobjekten + kd.eigene Parameter
A23: ZBC_ADDR_CHECK | B23: Nein | C23: Nein | J23: Reparaturprogramm: Prüfen Debitoren auf fehlende Adresse-Einträge in Archivierung
A24: ZBC_AL_REORG_OUT | B24: Nein | C24: Ja | F24: Ja | G24: Nein | J24: Archivelink Reorganisation - Erstellen Löschdatei und Tabelle für's Löschen von Sätzen in den Verknüpfungstabellen
A25: ZBC_AL_REORG_RETURN | B25: Nein | C25: Ja | F25: Ja | G25: Nein | J25: Archivelink Reorganisation - Rückantwort NE-Databridge
A26: ZBC_AL_REORG_VTABS | B26: Nein | C26: Ja | F26: Ja | G26: Nein | J26: Archivelink Reorganisation - Pflege der Verknüpfungstabellen
A27: ZBC_ANONYM_ZQ1 | B27: Nein | C27: Ja | F27: Ja | G27: Nein | J27: Anonymisierungstool in Q Systemen
A28: ZBC_BDCLOG_ALV | B28: Nein | C28: Ja | F28: Ja | G28: Nein | J28: Archivierte BDC Mappenprotokolle anzeigen
A29: ZBC_BDCLOG_ARCHIVE | B29: Nein | C29: Ja | F29: Ja | G29: Nein | J29: BDC Mappenprotokolle archivieren
A30: ZBC_BDCLOG_ARCHIVE_FIX | B30: Nein | C30: Ja | F30: Ja | G30: Nein | J30: BDC Mappenprotokolle archiv Objekte importieren
A31: ZBC_BELEG_VOLUME | B31: Nein | C31: Nein | J31: Ermittlung von Beleganzahl / -wert je Buchungskreis als Basis für Verteilschlüssel SAP Systempreis Verteilung
A32: ZBC_CALL_PROCEDURE | B32: Nein | C32: Nein | J32: Aufruf einer "Stored Procedure" in der Berichtswesendatenbank
A33: ZBC_CHECK_NRIV | B33: Nein | C33: Ja | F33: Ja | G33: Nein | J33: mit diesem Programm können Nummernkreise auf Fehler geprüft werden und freie Intervalle ermittelt werden.
A34: ZBC_COPY_DATASET | B34: Nein | C34: Ja | F34: Ja | G34: Nein | J34: Wird benötigt für ELMO für Dateiaufstellung für Netz HG105C. Es ist eine Kopie von ZFI_COPY_TEXT_DATASET ergänzt mit Archivierungsfunktionalität
A35: ZBC_EVENT_RAISE | B35: Ja | C35: Ja | E35: Ja | J35: Auslösen eines Kundenereignisses
A36: ZBC_EXCELTABUPLOAD | B36: Nein | C36: Nein | J36: Generischer Upload von Excel-Tabellen in R/3-Tabellen
A37: ZBC_F110_JOBCTRL | B37: Nein | C37: Offen | F37: ? | G37: ? | I37: J. Schaut | J37: Zahllauf Folgeverarbeitungssteuerung
A38: ZBC_F110_SPOOL_UPDATE | B38: Nein | C38: Offen | F38: ? | G38: ? | I38: J. Schaut | J38: Update von Spool-Datasets (Zahllaufversion)
A39: ZBC_FILE_DELETE | B39: Ja | C39: Ja | E39: Ja | J39: Dateienlöschung über Report ZBC_FILE_DELETE
A40: ZBC_FILE_EVENT_RAISE | B40: Ja | C40: Ja | E40: Ja | J40: Dateieneventauslösung
...

Sheet Tabelle3

Sheet Zuordnung Z-Programme zu DEVs
A1: Z-Programm in DEV für S/4 | B1: USR | C1: Welle 2 und 3 | D1: vorhanden in R/3 | E1: gesperrt | F1: Schnitt- stellen- programm | G1: Thema
A2: ZMM_MATREORG | B2: DEV-006 | D2: x | G2: Lagerver- und Materialverwaltung
A3: ZMM_MM60 | B3: DEV-006 | D3: x | G3: Lagerver- und Materialverwaltung
A4: ZMM_MM00 | B4: DEV-006 | D4: x | G4: Lagerver- und Materialverwaltung
A5: ZMM_MM01 | B5: DEV-006 | D5: x | G5: Lagerver- und Materialverwaltung
A6: ZMM_LAPS10 | B6: DEV-009 | D6: x | G6: Lagerplatzverwaltung
A7: ZMM_LAPS20 | B7: DEV-009 | D7: x | F7: x | G7: Lagerplatzverwaltung
A8: ZMM_LAPS30 | B8: DEV-009 | D8: x | G8: Lagerplatzverwaltung
A9: ZMM_LAPS40 | B9: DEV-009 | D9: x | F9: x | G9: Lagerplatzverwaltung
A10: ZMM_LAPS45 | B10: DEV-009 | D10: x | F10: x | G10: Lagerplatzverwaltung
A11: ZMM_LAPS52 | B11: DEV-009 | D11: x | G11: Lagerplatzverwaltung
A12: ZMM_LAPS70 | B12: DEV-009 | D12: x | F12: x | G12: Lagerplatzverwaltung
A13: ZMM_LAPS73 | B13: DEV-009 | D13: x | F13: x | G13: Lagerplatzverwaltung
A14: ZMM_LAPS75 | B14: DEV-009 | D14: x | G14: Lagerplatzverwaltung
A15: ZMM_LAPSDR | B15: DEV-009 | D15: x | F15: x | G15: Lagerplatzverwaltung
A16: ZMM_LPS | B16: DEV-009 | F16: x | G16: Lagerplatzverwaltung
A17: ZMM_INV | B17: DEV-010 | D17: x | G17: Inventurunterstützung
A18: ZMM_MI04 | B18: DEV-010 | D18: x | G18: Inventurunterstützung
A19: ZMM_INVDIF | B19: DEV-010 | D19: x | G19: Inventurunterstützung
A20: ZMM_MI31 | B20: DEV-010 | D20: x | G20: Inventurunterstützung
A21: ZMM_MI03 | B21: DEV-010 | G21: Inventurunterstützung
A22: ZFI_PAYMENT_AVIS | B22: DEV-012 | E22: x
A23: ALL-G08 | B23: DEV-021
A24: zsd_nast_archiv | B24: DEV-025 | D24: x
A25: ZFI_AVM_Upload_AUFNR_KFZ | B25: DEV-033 | D25: x | E25: x | F25: x | G25: MBC
A26: ZFI_AVM_Versicherung | B26: DEV-033 | D26: x | E26: x | G26: MBC
A27: ZFI_Mahns_Loesch | B27: DEV-034 | D27: x | E27: x | G27: Dispute Management
A28: ZFI_Mahns_Mahnv | B28: DEV-034 | D28: x | E28: x | G28: Dispute Management
A29: ZFI_MAHNSTOPP | B29: DEV-034 | D29: x | E29: x | G29: Dispute Management
A30: ZFI_MAHNSTOPP_ABZUG | B30: DEV-034 | D30: x | E30: x | G30: Dispute Management
A31: ZFI_Mahnstopp_Setzen | B31: DEV-034 | D31: x | E31: x | G31: Dispute Management
A32: ZFI_Mahnstopp2 | B32: DEV-034 | D32: x | E32: x | G32: Dispute Management
A33: ZFI_Mahnvorschlag | B33: DEV-035 | D33: x | E33: x | G33: Dispute Management
A34: ZFI_CCS_Auswert | B34: DEV-037 | D34: x | E34: x | G34: Dispute Management
A35: ZFI_CCS_Drucke | B35: DEV-037 | D35: x | E35: x | G35: Dispute Management
A36: ZFI_Druck_Container | B36: DEV-037 | D36: x | E36: x | G36: Dispute Management
A37: ZFI_Spool_Update | B37: DEV-037 | D37: x | E37: x | G37: Dispute Management
A38: ZFI_Inko_Cockpit | B38: DEV-038 | D38: x | E38: x | F38: x | G38: Dispute Management
A39: ZFI_Inko_Cockpit_Korrektur | B39: DEV-038 | D39: x | E39: x | F39: x | G39: Dispute Management
A40: ZFI_Rate01 | B40: DEV-038 | D40: x | E40: x | F40: x | G40: Dispute Management
...

Sheet ZProgramm-ZTransaktion - KOMPLE
A1: Programmname | B1: In meiner Liste? | C1: Beschreibung | D1: Programmtyp | E1: Für Welle 1 relevant? | F1: End-to-End-Prozess? | G1: 1. Schritt: Gap aus der Ramp-Up-Phase: Entsprechende Gaps durch das KDB freigegeben. | H1: 1. Schritt: - Nachjustierung: Entscheidung in Explorephase, Gap trotz Freigabe nicht zu übernehmen: | I1: Änderungen der Gaps/ Z-Artefakte nach Ramp-Up-Phase, die aber zu berücksichtigen sind. | J1: 2. Schritt: Z-Artefakte in Explorephase mit ADAC IT besprochen - über X - filtern: bisher keine Freigabe durch KDB | K1: 2. Schritt: Empfehlung zur Übernahme: Ja, Nein, tbd, nicht geklärt | L1: 2. Schritt: Kommentare zu den Z-Artefakten, die nicht in der Ramp-Up-Phase durch das KDB freigegeben wurden. | M1: Zuordnung zu den Userstorys bei Relevanz für Welle 1 | N1: Datei | O1: Freigabe (Filter auf ja) über KDB, da in Gapliste aus Ramp-Up-Phase enthalten | P1: Status für Übernahme nicht über Gapliste, sondern aus Beurteilung der Transaktionen in Z-Artefaktenliste von Johannes und Volker | Q1: vorherige Bewertung Übernahme
A2: Z_CLEAN_EVTTAB | B2: =VLOOKUP(A2,'Z-Programme'!$A$2:$A$650,1,FALSE) -> Z_CLEAN_EVTTAB | C2: Hilfsprogramm zur Bereinigung Inkonsistenzen in Jobtabelle BTCEVTJOB | D2: 1 Ausführbares Programm | E2: Grundsätzlich Nein: für keine Welle relevant | F2: Utitilites/SAP Supportpackage | J2: X | K2: Nein, keine Übernahme | L2: Roland, 27.5.2024: Nein, nicht übernehmen, mit Johannes geklärt. | N2: =IF(#REF!="Ja",VLOOKUP(A2,'[1]ZArtefakte aus Listen'!A:B,2,0),"") -> #REF! | Q2: =IF(#REF!="Ja",VLOOKUP(A2,'[1]ZArtefakte aus Listen'!A:D,4,0),"") -> #REF!
A3: Z_IDOC_STATUS_SET | B3: =VLOOKUP(A3,'Z-Programme'!$A$2:$A$650,1,FALSE) -> Z_IDOC_STATUS_SET | C3: Idoc Status auf erledigt setzen | D3: 1 Ausführbares Programm | E3: Ja, Übernahme, aber nicht relevant für Welle 1 | F3: I2C - Utilites Warenwirtschaft ETM | J3: X | K3: Ja, Übernahme | L3: Roland, 27.5.204: Ja, wird benötigt, aber nicht in Welle 1; geklärt mit J. Schaut und V. Niemann | N3: =IF(#REF!="Ja",VLOOKUP(A3,'[1]ZArtefakte aus Listen'!A:B,2,0),"") -> #REF! | Q3: =IF(#REF!="Ja",VLOOKUP(A3,'[1]ZArtefakte aus Listen'!A:D,4,0),"") -> #REF!
A4: Z_INFO_PRICING_SERVICES_USER | B4: =VLOOKUP(A4,'Z-Programme'!$A$2:$A$650,1,FALSE) -> Z_INFO_PRICING_SERVICES_USER | C4: Z_INFO_PRICING_SERVICES_USER lt. SAP Hinweis 1786263 | D4: 1 Ausführbares Programm | E4: Grundsätzlich Nein: für keine Welle relevant | F4: Irrelevant | J4: X | K4: Nein, keine Übernahme | L4: Roland, 15.11.2023: Nein, bezieht sich auf einen Hinweis aus 2018. | N4: =IF(#REF!="Ja",VLOOKUP(A4,'[1]ZArtefakte aus Listen'!A:B,2,0),"") -> #REF! | Q4: =IF(#REF!="Ja",VLOOKUP(A4,'[1]ZArtefakte aus Listen'!A:D,4,0),"") -> #REF!
A5: Z_REPAIR_ADRNR_1 | B5: =VLOOKUP(A5,'Z-Programme'!$A$2:$A$650,1,FALSE) -> Z_REPAIR_ADRNR_1 | C5: Reparatur der Adressinkonsistenz in Tabelle VBPA und KNA1 | D5: 1 Ausführbares Programm | E5: Grundsätzlich Nein: für keine Welle relevant | F5: Irrelevant | J5: X | K5: Nein, keine Übernahme | L5: Kilian, 15.11.2023: Nein, müsste oboselt sein, auch wegen neues BP-Ansatz. | N5: =IF(#REF!="Ja",VLOOKUP(A5,'[1]ZArtefakte aus Listen'!A:B,2,0),"") -> #REF! | Q5: =IF(#REF!="Ja",VLOOKUP(A5,'[1]ZArtefakte aus Listen'!A:D,4,0),"") -> #REF!
A6: Z_SAPMZSWA | B6: =VLOOKUP(A6,'Z-Programme'!$A$2:$A$650,1,FALSE) -> Z_SAPMZSWA | C6: Programm SAPMZSWA | D6: M Modulpool | E6: Ja, Übernahme, aber nicht relevant für Welle 1 | F6: I2C | J6: X | K6: Ja, Übernahme | L6: Roland, 27.5.204: Ja, wird benötigt, aber nicht in Welle 1; geklärt mit J. Schaut und V. Niemann | N6: =IF(#REF!="Ja",VLOOKUP(A6,'[1]ZArtefakte aus Listen'!A:B,2,0),"") -> #REF! | Q6: =IF(#REF!="Ja",VLOOKUP(A6,'[1]ZArtefakte aus Listen'!A:D,4,0),"") -> #REF!
A7: Z_SAPMZSWA_MENUE | B7: =VLOOKUP(A7,'Z-Programme'!$A$2:$A$650,1,FALSE) -> Z_SAPMZSWA_MENUE | C7: Menü Batterieservice | D7: M Modulpool | E7: Ja, Übernahme, aber nicht relevant für Welle 1 | F7: I2C | J7: X | K7: Ja, Übernahme | L7: Roland, 27.5.204: Ja, wird benötigt, aber nicht in Welle 1; geklärt mit J. Schaut und V. Niemann | N7: =IF(#REF!="Ja",VLOOKUP(A7,'[1]ZArtefakte aus Listen'!A:B,2,0),"") -> #REF! | Q7: =IF(#REF!="Ja",VLOOKUP(A7,'[1]ZArtefakte aus Listen'!A:D,4,0),"") -> #REF!
A8: Z_SAPMZSWAT | B8: =VLOOKUP(A8,'Z-Programme'!$A$2:$A$650,1,FALSE) -> Z_SAPMZSWAT | C8: Modulpool: Elektronisches Bezahlen SWA-Terminal | D8: M Modulpool | E8: Ja, Übernahme, aber nicht relevant für Welle 1 | F8: I2C | J8: X | K8: Ja, Übernahme | L8: Roland, 27.5.204: Ja, wird benötigt, aber nicht in Welle 1; geklärt mit J. Schaut und V. Niemann | N8: =IF(#REF!="Ja",VLOOKUP(A8,'[1]ZArtefakte aus Listen'!A:B,2,0),"") -> #REF! | Q8: =IF(#REF!="Ja",VLOOKUP(A8,'[1]ZArtefakte aus Listen'!A:D,4,0),"") -> #REF!
A9: Z0SAP_12 | B9: =VLOOKUP(A9,'Z-Programme'!$A$2:$A$650,1,FALSE) -> Z0SAP_12 | C9: Datendatei-View: Geplante Abschreibungen auf Anlagen | D9: 1 Ausführbares Programm | E9: Grundsätzlich Nein: für keine Welle relevant | F9: A2R - Utitlities Anlagenmanagement | K9: Nein, keine Übernahme | L9: Roland, 12.6.2024: Info von Johannes Schaut per Mail. Nicht relevant für keine Welle | M9: X | N9: =IF(#REF!="Ja",VLOOKUP(A9,'[1]ZArtefakte aus Listen'!A:B,2,0),"") -> #REF! | Q9: =IF(#REF!="Ja",VLOOKUP(A9,'[1]ZArtefakte aus Listen'!A:D,4,0),"") -> #REF!
A10: ZAA_ANLAGENTR_COPY_LANGTEXT | B10: =VLOOKUP(A10,'Z-Programme'!$A$2:$A$650,1,FALSE) -> ZAA_ANLAGENTR_COPY_LANGTEXT | C10: Anlagentransfer Langtexte kopieren | D10: 1 Ausführbares Programm | E10: Grundsätzlich Nein: für keine Welle relevant | F10: Irrelevant | J10: X | K10: Nein, keine Übernahme | L10: Roland, 15.11.2023: Nein, Rückführung auf den SAP Standard gemäß Projektvorgabe. | N10: =IF(#REF!="Ja",VLOOKUP(A10,'[1]ZArtefakte aus Listen'!A:B,2,0),"") -> #REF! | Q10: =IF(#REF!="Ja",VLOOKUP(A10,'[1]ZArtefakte aus Listen'!A:D,4,0),"") -> #REF!
A11: ZAA_ANLAGENTRANSFER | B11: =VLOOKUP(A11,'Z-Programme'!$A$2:$A$650,1,FALSE) -> ZAA_ANLAGENTRANSFER | C11: Anlagentransfer | D11: 1 Ausführbares Programm | E11: Grundsätzlich Nein: für keine Welle relevant | F11: Irrelevant | J11: X | K11: Nein, keine Übernahme | L11: Roland, 15.11.2023: Nein, Rückführung auf den SAP Standard gemäß Projektvorgabe. | N11: =IF(#REF!="Ja",VLOOKUP(A11,'[1]ZArtefakte aus Listen'!A:B,2,0),"") -> #REF! | Q11: =IF(#REF!="Ja",VLOOKUP(A11,'[1]ZArtefakte aus Listen'!A:D,4,0),"") -> #REF!
A12: ZAA_CO_KONTIERUNG | B12: =VLOOKUP(A12,'Z-Programme'!$A$2:$A$650,1,FALSE) -> ZAA_CO_KONTIERUNG | C12: Änderung von Innenaufträgen/Kostenstellen in Anlagen | D12: 1 Ausführbares Programm | E12: Grundsätzlich Nein: für keine Welle relevant | F12: Irrelevant | J12: X | K12: Nein, keine Übernahme | L12: Roland, 15.11.2023: Nein, Rückführung auf den SAP Standard gemäß Projektvorgabe. | N12: =IF(#REF!="Ja",VLOOKUP(A12,'[1]ZArtefakte aus Listen'!A:B,2,0),"") -> #REF! | Q12: =IF(#REF!="Ja",VLOOKUP(A12,'[1]ZArtefakte aus Listen'!A:D,4,0),"") -> #REF!
A13: ZAA_INVE01 | B13: =VLOOKUP(A13,'Z-Programme'!$A$2:$A$650,1,FALSE) -> ZAA_INVE01 | C13: Inventurliste nach Anlagennummern / Anlagentext | D13: 1 Ausführbares Programm | E13: Grundsätzlich Nein: für keine Welle relevant | F13: Irrelevant | J13: X | K13: Nein, keine Übernahme | L13: Roland, 15.11.2023: Nein, Rückführung auf den SAP Standard gemäß Projektvorgabe. | N13: =IF(#REF!="Ja",VLOOKUP(A13,'[1]ZArtefakte aus Listen'!A:B,2,0),"") -> #REF! | Q13: =IF(#REF!="Ja",VLOOKUP(A13,'[1]ZArtefakte aus Listen'!A:D,4,0),"") -> #REF!
A14: ZAA_INVE06 | B14: =VLOOKUP(A14,'Z-Programme'!$A$2:$A$650,1,FALSE) -> ZAA_INVE06 | C14: Inventurliste nach Anlagennummern / Anlagentext | D14: 1 Ausführbares Programm | E14: Grundsätzlich Nein: für keine Welle relevant | F14: Irrelevant | J14: X | K14: Nein, keine Übernahme | L14: Roland, 15.11.2023: Nein, Rückführung auf den SAP Standard gemäß Projektvorgabe. | N14: =IF(#REF!="Ja",VLOOKUP(A14,'[1]ZArtefakte aus Listen'!A:B,2,0),"") -> #REF! | Q14: =IF(#REF!="Ja",VLOOKUP(A14,'[1]ZArtefakte aus Listen'!A:D,4,0),"") -> #REF!
A15: ZAA_INVE07 | B15: =VLOOKUP(A15,'Z-Programme'!$A$2:$A$650,1,FALSE) -> ZAA_INVE07 | C15: Inventurliste nach Kostenrechnungsobjekten | D15: 1 Ausführbares Programm | E15: Grundsätzlich Nein: für keine Welle relevant | F15: Irrelevant | J15: X | K15: Nein, keine Übernahme | L15: Roland, 15.11.2023: Nein, Rückführung auf den SAP Standard gemäß Projektvorgabe. | N15: =IF(#REF!="Ja",VLOOKUP(A15,'[1]ZArtefakte aus Listen'!A:B,2,0),"") -> #REF! | Q15: =IF(#REF!="Ja",VLOOKUP(A15,'[1]ZArtefakte aus Listen'!A:D,4,0),"") -> #REF!
A16: ZAA_MASS_DOWN | B16: =VLOOKUP(A16,'Z-Programme'!$A$2:$A$650,1,FALSE) -> ZAA_MASS_DOWN | C16: Anlagenstamm Massenänderung: Download | D16: 1 Ausführbares Programm | E16: Grundsätzlich Nein: für keine Welle relevant | F16: Irrelevant | G16: Finance Gapliste: Gap 01-(A2R-03.06) | H16: Nein, keine Übernahme: Abstimmung mit NTT und Fr. Brahms am 12.3.2024 | I16: Ursprünglich freigegeben im KDB, wird aber nicht mehr benötigt. | K16: Nein, keine Übernahme | L16: Roland, 9.7.2024: Nachträgliche Änderung zum KDB-Beschluss, da Z-Artefakte als obsolet angesehen werden. | N16: =IF(#REF!="Ja",VLOOKUP(A16,'[1]ZArtefakte aus Listen'!A:B,2,0),"") -> #REF! | Q16: =IF(#REF!="Ja",VLOOKUP(A16,'[1]ZArtefakte aus Listen'!A:D,4,0),"") -> #REF!
A17: ZAA_MASS_UP | B17: =VLOOKUP(A17,'Z-Programme'!$A$2:$A$650,1,FALSE) -> ZAA_MASS_UP | C17: Massenänderung Anlagenstamm: Upload CSV-Datei | D17: 1 Ausführbares Programm | E17: Grundsätzlich Nein: für keine Welle relevant | F17: Irrelevant | G17: Finance Gapliste: Gap 01-(A2R-03.06) | H17: Nein, keine Übernahme: Abstimmung mit NTT und Fr. Brahms am 12.3.2024 | I17: Ursprünglich freigegeben im KDB, wird aber nicht mehr benötigt. | K17: Nein, keine Übernahme | L17: Roland, 9.7.2024: Nachträgliche Änderung zum KDB-Beschluss, da Z-Artefakte als obsolet angesehen werden. | N17: =IF(#REF!="Ja",VLOOKUP(A17,'[1]ZArtefakte aus Listen'!A:B,2,0),"") -> #REF! | Q17: =IF(#REF!="Ja",VLOOKUP(A17,'[1]ZArtefakte aus Listen'!A:D,4,0),"") -> #REF!
A18: ZAA_RAHIST01 | B18: =VLOOKUP(A18,'Z-Programme'!$A$2:$A$650,1,FALSE) -> ZAA_RAHIST01 | C18: Anlagenhistorie | D18: 1 Ausführbares Programm | E18: Grundsätzlich Nein: für keine Welle relevant | F18: Irrelevant | J18: X | K18: Nein, keine Übernahme | L18: Roland, 15.11.2023: Nein, Rückführung auf den SAP Standard gemäß Projektvorgabe. | N18: =IF(#REF!="Ja",VLOOKUP(A18,'[1]ZArtefakte aus Listen'!A:B,2,0),"") -> #REF! | Q18: =IF(#REF!="Ja",VLOOKUP(A18,'[1]ZArtefakte aus Listen'!A:D,4,0),"") -> #REF!
A19: ZAA_RAPOST2010 | B19: =VLOOKUP(A19,'Z-Programme'!$A$2:$A$650,1,FALSE) -> ZAA_RAPOST2010 | C19: Buchen der Abschreibungen | D19: 1 Ausführbares Programm | E19: Grundsätzlich Nein: für keine Welle relevant | F19: Irrelevant | J19: X | K19: Nein, keine Übernahme | L19: Roland, 15.11.2023: Nein, Rückführung auf den SAP Standard gemäß Projektvorgabe. | N19: =IF(#REF!="Ja",VLOOKUP(A19,'[1]ZArtefakte aus Listen'!A:B,2,0),"") -> #REF! | Q19: =IF(#REF!="Ja",VLOOKUP(A19,'[1]ZArtefakte aus Listen'!A:D,4,0),"") -> #REF!
A20: ZAA_STAMMDAT_ALV | B20: =VLOOKUP(A20,'Z-Programme'!$A$2:$A$650,1,FALSE) -> ZAA_STAMMDAT_ALV | C20: Stammdaten-Auswertung ALV-Liste ( mehrzeilig ) | D20: 1 Ausführbares Programm | E20: Grundsätzlich Nein: für keine Welle relevant | F20: Irrelevant | G20: Finance Gapliste: Gap 01-(A2R-03.06) | H20: Nein, keine Übernahme: Abstimmung mit NTT und Fr. Brahms am 12.3.2024 | I20: Ursprünglich freigegeben im KDB, wird aber nicht mehr benötigt. | K20: Nein, keine Übernahme | L20: Roland, 9.7.2024: Nachträgliche Änderung zum KDB-Beschluss, da Z-Artefakte als obsolet angesehen werden. | N20: =IF(#REF!="Ja",VLOOKUP(A20,'[1]ZArtefakte aus Listen'!A:B,2,0),"") -> #REF! | Q20: =IF(#REF!="Ja",VLOOKUP(A20,'[1]ZArtefakte aus Listen'!A:D,4,0),"") -> #REF!
A21: ZACAC_DATA_TRANSFER | B21: =VLOOKUP(A21,'Z-Programme'!$A$2:$A$650,1,FALSE) -> ZACAC_DATA_TRANSFER | C21: Übernahme von Debitoren-/Kreditorenrechnungen in die Accrual Engine | D21: 1 Ausführbares Programm | E21: Ja, in Welle 1 relevant | F21: R2R - Abschreibungen Accrual Engine | J21: X | K21: Ja, Übernahme | L21: Roland, 27.5.2024: Ja, wird benötigt, geklärt mit Johannes Schaut | M21: X | N21: =IF(#REF!="Ja",VLOOKUP(A21,'[1]ZArtefakte aus Listen'!A:B,2,0),"") -> #REF! | Q21: =IF(#REF!="Ja",VLOOKUP(A21,'[1]ZArtefakte aus Listen'!A:D,4,0),"") -> #REF!
A22: ZACAC_DSITEMS | B22: =VLOOKUP(A22,'Z-Programme'!$A$2:$A$650,1,FALSE) -> ZACAC_DSITEMS | C22: Anzeigen von Abgrenzungsobjekten + kd.eigene Parameter | D22: 1 Ausführbares Programm | E22: Ja, in Welle 1 relevant | F22: R2R - Abschreibungen Accrual Engine | J22: X | K22: Ja, Übernahme | L22: Roland, 27.5.2024: Ja, wird benötigt, geklärt mit Johannes Schaut | M22: X | N22: =IF(#REF!="Ja",VLOOKUP(A22,'[1]ZArtefakte aus Listen'!A:B,2,0),"") -> #REF! | Q22: =IF(#REF!="Ja",VLOOKUP(A22,'[1]ZArtefakte aus Listen'!A:D,4,0),"") -> #REF!
A23: ZBC_ADDR_CHECK | B23: =VLOOKUP(A23,'Z-Programme'!$A$2:$A$650,1,FALSE) -> ZBC_ADDR_CHECK | C23: Prüfen Debitoren auf fehlende Adresse-Einträge | D23: 1 Ausführbares Programm | E23: Ja, in Welle 1 relevant | F23: Kein Prozess: wird in der ADAC SAP-Basis benötigt. | J23: X | K23: Ja, Übernahme | L23: Roland, 27.5.2024: Funktionalitäten, die auch unter S/4HANA durch die ADAC SAP Basis benötigt werden. | N23: =IF(#REF!="Ja",VLOOKUP(A23,'[1]ZArtefakte aus Listen'!A:B,2,0),"") -> #REF! | Q23: =IF(#REF!="Ja",VLOOKUP(A23,'[1]ZArtefakte aus Listen'!A:D,4,0),"") -> #REF!
A24: ZBC_AL_REORG_OUT | B24: =VLOOKUP(A24,'Z-Programme'!$A$2:$A$650,1,FALSE) -> ZBC_AL_REORG_OUT | C24: Archivelink Reorganisation - Erstellen Löschdatei | D24: 1 Ausführbares Programm | E24: Ja, in Welle 1 relevant | F24: Kein Prozess: wird in der ADAC SAP-Basis benötigt. | J24: X | K24: Ja, Übernahme | L24: Roland, 27.5.2024: Funktionalitäten, die auch unter S/4HANA durch die ADAC SAP Basis benötigt werden. | N24: =IF(#REF!="Ja",VLOOKUP(A24,'[1]ZArtefakte aus Listen'!A:B,2,0),"") -> #REF! | Q24: =IF(#REF!="Ja",VLOOKUP(A24,'[1]ZArtefakte aus Listen'!A:D,4,0),"") -> #REF!
A25: ZBC_AL_REORG_RETURN | B25: =VLOOKUP(A25,'Z-Programme'!$A$2:$A$650,1,FALSE) -> ZBC_AL_REORG_RETURN | C25: Archivelink Reorganisation - Rückantwort NE-Databridge | D25: 1 Ausführbares Programm | E25: Ja, in Welle 1 relevant | F25: Kein Prozess: wird in der ADAC SAP-Basis benötigt. | J25: X | K25: Ja, Übernahme | L25: Roland, 27.5.2024: Funktionalitäten, die auch unter S/4HANA durch die ADAC SAP Basis benötigt werden. | N25: =IF(#REF!="Ja",VLOOKUP(A25,'[1]ZArtefakte aus Listen'!A:B,2,0),"") -> #REF! | Q25: =IF(#REF!="Ja",VLOOKUP(A25,'[1]ZArtefakte aus Listen'!A:D,4,0),"") -> #REF!
A26: ZBC_AL_REORG_VTABS | B26: =VLOOKUP(A26,'Z-Programme'!$A$2:$A$650,1,FALSE) -> ZBC_AL_REORG_VTABS | C26: Archivelink: Pflege der Verknüpfungstabellen | D26: 1 Ausführbares Programm | E26: Ja, in Welle 1 relevant | F26: Kein Prozess: wird in der ADAC SAP-Basis benötigt. | J26: X | K26: Ja, Übernahme | L26: Roland, 27.5.2024: Funktionalitäten, die auch unter S/4HANA durch die ADAC SAP Basis benötigt werden. | N26: =IF(#REF!="Ja",VLOOKUP(A26,'[1]ZArtefakte aus Listen'!A:B,2,0),"") -> #REF! | Q26: =IF(#REF!="Ja",VLOOKUP(A26,'[1]ZArtefakte aus Listen'!A:D,4,0),"") -> #REF!
A27: ZBC_ANONYM_ZQ1 | B27: =VLOOKUP(A27,'Z-Programme'!$A$2:$A$650,1,FALSE) -> ZBC_ANONYM_ZQ1 | C27: Programm ZBC_ANONYM_ZQ1 | D27: 1 Ausführbares Programm | E27: Ja, in Welle 1 relevant | F27: Kein Prozess: wird in der ADAC SAP-Basis benötigt. | J27: X | K27: Ja, Übernahme | L27: Roland, 27.5.2024: Funktionalitäten, die auch unter S/4HANA durch die ADAC SAP Basis benötigt werden. | N27: =IF(#REF!="Ja",VLOOKUP(A27,'[1]ZArtefakte aus Listen'!A:B,2,0),"") -> #REF! | Q27: =IF(#REF!="Ja",VLOOKUP(A27,'[1]ZArtefakte aus Listen'!A:D,4,0),"") -> #REF!
A28: ZBC_BDCLOG_ALV | B28: =VLOOKUP(A28,'Z-Programme'!$A$2:$A$650,1,FALSE) -> ZBC_BDCLOG_ALV | C28: Archivierte BDC Mappenprotokolle anzeigen | D28: 1 Ausführbares Programm | E28: Ja, in Welle 1 relevant | F28: Kein Prozess: wird in der ADAC SAP-Basis benötigt. | J28: X | K28: Ja, Übernahme | L28: Roland, 27.5.2024: Funktionalitäten, die auch unter S/4HANA durch die ADAC SAP Basis benötigt werden. | N28: =IF(#REF!="Ja",VLOOKUP(A28,'[1]ZArtefakte aus Listen'!A:B,2,0),"") -> #REF! | Q28: =IF(#REF!="Ja",VLOOKUP(A28,'[1]ZArtefakte aus Listen'!A:D,4,0),"") -> #REF!
A29: ZBC_BDCLOG_ARCHIVE | B29: =VLOOKUP(A29,'Z-Programme'!$A$2:$A$650,1,FALSE) -> ZBC_BDCLOG_ARCHIVE | C29: BDC Mappenprotokolle archivieren | D29: 1 Ausführbares Programm | E29: Ja, in Welle 1 relevant | F29: Kein Prozess: wird in der ADAC SAP-Basis benötigt. | J29: X | K29: Ja, Übernahme | L29: Roland, 27.5.2024: Funktionalitäten, die auch unter S/4HANA durch die ADAC SAP Basis benötigt werden. | N29: =IF(#REF!="Ja",VLOOKUP(A29,'[1]ZArtefakte aus Listen'!A:B,2,0),"") -> #REF! | Q29: =IF(#REF!="Ja",VLOOKUP(A29,'[1]ZArtefakte aus Listen'!A:D,4,0),"") -> #REF!
A30: ZBC_BDCLOG_ARCHIVE_FIX | B30: =VLOOKUP(A30,'Z-Programme'!$A$2:$A$650,1,FALSE) -> ZBC_BDCLOG_ARCHIVE_FIX | C30: BDC Mappenprotokolle archiv Objekte importieren | D30: 1 Ausführbares Programm | E30: Ja, in Welle 1 relevant | F30: Kein Prozess: wird in der ADAC SAP-Basis benötigt. | J30: X | K30: Ja, Übernahme | L30: Roland, 27.5.2024: Funktionalitäten, die auch unter S/4HANA durch die ADAC SAP Basis benötigt werden. | N30: =IF(#REF!="Ja",VLOOKUP(A30,'[1]ZArtefakte aus Listen'!A:B,2,0),"") -> #REF! | Q30: =IF(#REF!="Ja",VLOOKUP(A30,'[1]ZArtefakte aus Listen'!A:D,4,0),"") -> #REF!
A31: ZBC_BELEG_VOLUME | B31: =VLOOKUP(A31,'Z-Programme'!$A$2:$A$650,1,FALSE) -> ZBC_BELEG_VOLUME | C31: Anzahl Positionen von Belegarten für ECC-Systeme | D31: 1 Ausführbares Programm | E31: Ja, in Welle 1 relevant | F31: Kein Prozess: wird in der ADAC SAP-Basis benötigt. | J31: X | K31: Ja, Übernahme | L31: Roland, 27.5.2024: Funktionalitäten, die auch unter S/4HANA durch die ADAC SAP Basis benötigt werden. | N31: =IF(#REF!="Ja",VLOOKUP(A31,'[1]ZArtefakte aus Listen'!A:B,2,0),"") -> #REF! | Q31: =IF(#REF!="Ja",VLOOKUP(A31,'[1]ZArtefakte aus Listen'!A:D,4,0),"") -> #REF!
A32: ZBC_CALL_PROCEDURE | B32: =VLOOKUP(A32,'Z-Programme'!$A$2:$A$650,1,FALSE) -> ZBC_CALL_PROCEDURE | C32: Aufruf einer "Stored Procedure" in der Berichtswesendatenbank | D32: 1 Ausführbares Programm | E32: Grundsätzlich Nein: für keine Welle relevant | F32: Irrelevant | J32: X | K32: Nein, keine Übernahme | L32: Roland: 22.03.2024: Nein, entfällt, da neue Lösung | N32: =IF(#REF!="Ja",VLOOKUP(A32,'[1]ZArtefakte aus Listen'!A:B,2,0),"") -> #REF! | Q32: =IF(#REF!="Ja",VLOOKUP(A32,'[1]ZArtefakte aus Listen'!A:D,4,0),"") -> #REF!
A33: ZBC_CHECK_NRIV | B33: =VLOOKUP(A33,'Z-Programme'!$A$2:$A$650,1,FALSE) -> ZBC_CHECK_NRIV | C33: Nummernkreise prüfen | D33: 1 Ausführbares Programm | E33: Ja, in Welle 1 relevant | F33: Kein Prozess: wird in der ADAC SAP-Basis benötigt. | J33: X | K33: Ja, Übernahme | L33: Roland, 27.5.2024: Funktionalitäten, die auch unter S/4HANA durch die ADAC SAP Basis benötigt werden. | N33: =IF(#REF!="Ja",VLOOKUP(A33,'[1]ZArtefakte aus Listen'!A:B,2,0),"") -> #REF! | Q33: =IF(#REF!="Ja",VLOOKUP(A33,'[1]ZArtefakte aus Listen'!A:D,4,0),"") -> #REF!
A34: ZBC_COPY_DATASET | B34: =VLOOKUP(A34,'Z-Programme'!$A$2:$A$650,1,FALSE) -> ZBC_COPY_DATASET | C34: Kopieren Dataset mit Archivierung | D34: 1 Ausführbares Programm | E34: Ja, in Welle 1 relevant | F34: Kein Prozess: wird in der ADAC SAP-Basis benötigt. | J34: X | K34: Ja, Übernahme | L34: Roland, 27.5.2024: Funktionalitäten, die auch unter S/4HANA durch die ADAC SAP Basis benötigt werden. | N34: =IF(#REF!="Ja",VLOOKUP(A34,'[1]ZArtefakte aus Listen'!A:B,2,0),"") -> #REF! | Q34: =IF(#REF!="Ja",VLOOKUP(A34,'[1]ZArtefakte aus Listen'!A:D,4,0),"") -> #REF!
... A42: ZBC_JOB_ABORT | B42: =VLOOKUP(A42,'Z-Programme'!$A$2:$A$650,1,FALSE) -> ZBC_JOB_ABORT | C42: Job Abbrechen wenn eine Liste best. String enthält | D42: 1 Ausführbares Programm | E42: Ja, in Welle 1 relevant | F42: Kein Prozess: wird in der ADAC SAP-Basis benötigt. | J42: X | K42: Ja, Übernahme | L42: Roland, 27.5.2024: Funktionalitäten, die auch unter S/4HANA durch die ADAC SAP Basis benötigt werden. | N42: =IF(#REF!="Ja",VLOOKUP(A42,'[1]ZArtefakte aus Listen'!A:B,2,0),"") -> #REF! | Q42: =IF(#REF!="Ja",VLOOKUP(A42,'[1]ZArtefakte aus Listen'!A:D,4,0),"") -> #REF!
A43: ZBC_JOBCONTROL | B43: =VLOOKUP(A43,'Z-Programme'!$A$2:$A$650,1,FALSE) -> ZBC_JOBCONTROL | D43: 1 Ausführbares Programm | E43: Ja, in Welle 1 relevant | F43: Kein Prozess: wird in der ADAC SAP-Basis benötigt. | J43: X | K43: Ja, Übernahme | L43: Roland, 27.5.2024: Funktionalitäten, die auch unter S/4HANA durch die ADAC SAP Basis benötigt werden. | N43: =IF(#REF!="Ja",VLOOKUP(A43,'[1]ZArtefakte aus Listen'!A:B,2,0),"") -> #REF! | Q43: =IF(#REF!="Ja",VLOOKUP(A43,'[1]ZArtefakte aus Listen'!A:D,4,0),"") -> #REF!
A44: ZBC_LOEVM_DEBI_KREDI | B44: =VLOOKUP(A44,'Z-Programme'!$A$2:$A$650,1,FALSE) -> ZBC_LOEVM_DEBI_KREDI | C44: Programm zur Pflege der Löschvormerkung für Debitoren und Kreditoren | D44: 1 Ausführbares Programm | E44: Ja, in Welle 1 relevant | F44: Kein Prozess: wird in der ADAC SAP-Basis benötigt. | J44: X | K44: Ja, Übernahme | L44: Roland, 27.5.2024: Funktionalitäten, die auch unter S/4HANA durch die ADAC SAP Basis benötigt werden. | N44: =IF(#REF!="Ja",VLOOKUP(A44,'[1]ZArtefakte aus Listen'!A:B,2,0),"") -> #REF! | Q44: =IF(#REF!="Ja",VLOOKUP(A44,'[1]ZArtefakte aus Listen'!A:D,4,0),"") -> #REF!
A45: ZBC_LOEVM_DEBI_KREDI_2 | B45: =VLOOKUP(A45,'Z-Programme'!$A$2:$A$650,1,FALSE) -> ZBC_LOEVM_DEBI_KREDI_2 | C45: Setzen Löschvormerkung anhand Tage ohne Buchungen | D45: 1 Ausführbares Programm | E45: Ja, in Welle 1 relevant | F45: Kein Prozess: wird in der ADAC SAP-Basis benötigt. | J45: X | K45: Ja, Übernahme | L45: Roland, 27.5.2024: Funktionalitäten, die auch unter S/4HANA durch die ADAC SAP Basis benötigt werden. | N45: =IF(#REF!="Ja",VLOOKUP(A45,'[1]ZArtefakte aus Listen'!A:B,2,0),"") -> #REF! | Q45: =IF(#REF!="Ja",VLOOKUP(A45,'[1]ZArtefakte aus Listen'!A:D,4,0),"") -> #REF!
A46: ZBC_LOGO_SWITCH | B46: =VLOOKUP(A46,'Z-Programme'!$A$2:$A$650,1,FALSE) -> ZBC_LOGO_SWITCH | C46: Logo-Clicks ein/ausschalten | D46: 1 Ausführbares Programm | E46: Ja, in Welle 1 relevant | F46: Kein Prozess: wird in der ADAC SAP-Basis benötigt. | J46: X | K46: Ja, Übernahme | L46: Roland, 27.5.2024: Funktionalitäten, die auch unter S/4HANA durch die ADAC SAP Basis benötigt werden. | N46: =IF(#REF!="Ja",VLOOKUP(A46,'[1]ZArtefakte aus Listen'!A:B,2,0),"") -> #REF! | Q46: =IF(#REF!="Ja",VLOOKUP(A46,'[1]ZArtefakte aus Listen'!A:D,4,0),"") -> #REF!
A47: ZBC_MAESTRO | B47: =VLOOKUP(A47,'Z-Programme'!$A$2:$A$650,1,FALSE) -> ZBC_MAESTRO | C47: ZBC_MAESTRO | D47: 1 Ausführbares Programm | E47: Grundsätzlich Nein: für keine Welle relevant | F47: Irrelevant | J47: X | K47: Nein, keine Übernahme | L47: Roland: 22.03.2024: Nein, entfällt, da neue Lösung | N47: =IF(#REF!="Ja",VLOOKUP(A47,'[1]ZArtefakte aus Listen'!A:B,2,0),"") -> #REF! | Q47: =IF(#REF!="Ja",VLOOKUP(A47,'[1]ZArtefakte aus Listen'!A:D,4,0),"") -> #REF!
...

Sheet CALM
A1: USR | B1: Status | C1: Timebox
A2: DEV-005 | B2: Nicht relevant | C2: Realize W1 | D2: S2P
A3: DEV-008 | B3: Nicht relevant | C3: Realize W1 | D3: S2P
A4: DEV-010 | B4: In Bearbeitung | C4: Realize W1 | D4: S2P | E4: =VLOOKUP(A4,'Z-Programme'!#REF!,1,FALSE) -> #REF!
A5: DEV-003 | B5: Nicht relevant | C5: Realize W1 | D5: R2R
A6: DEV-012 | B6: Nicht relevant | C6: MS-Entwicklungsphase 2 | D6: S2P
A7: DEV-014 | B7: Nicht relevant | C7: MS-Entwicklungsphase 3 | D7: I2C
A8: DEV-016 | B8: Nicht relevant | C8: MS-Entwicklungsphase 3 | D8: I2C
A9: DEV-021 | B9: In Bearbeitung | C9: Realize W1 | D9: I2C
A10: DEV-025 | B10: In Bearbeitung | C10: Realize W1 | D10: I2C | E10: =VLOOKUP(A10,'Z-Programme'!#REF!,1,FALSE) -> #REF!
A11: DEV-033 | B11: In Bearbeitung | C11: MS-Entwicklungsphase 2 | D11: I2C | E11: =VLOOKUP(A11,'Z-Programme'!#REF!,1,FALSE) -> #REF!
A12: DEV-034 | B12: Nicht relevant | C12: MS-Entwicklungsphase 2 | D12: I2C | E12: =VLOOKUP(A12,'Z-Programme'!#REF!,1,FALSE) -> #REF!
A13: DEV-035 | B13: In Bearbeitung | C13: MS-Entwicklungsphase 2 | D13: I2C | E13: =VLOOKUP(A13,'Z-Programme'!#REF!,1,FALSE) -> #REF!
A14: DEV-036 | B14: Nicht relevant | C14: MS-Entwicklungsphase 2 | D14: I2C
A15: DEV-037 | B15: Gesperrt | C15: MS-Entwicklungsphase 2 | D15: I2C | E15: =VLOOKUP(A15,'Z-Programme'!#REF!,1,FALSE) -> #REF!
A16: DEV-038 | B16: Nicht relevant | C16: MS-Entwicklungsphase 2 | D16: I2C | E16: =VLOOKUP(A16,'Z-Programme'!#REF!,1,FALSE) -> #REF!
A17: DEV-039 | B17: Nicht relevant | C17: MS-Entwicklungsphase 2 | D17: I2C | E17: =VLOOKUP(A17,'Z-Programme'!#REF!,1,FALSE) -> #REF!
A18: DEV-040 | B18: Nicht relevant | C18: MS-Entwicklungsphase 2 | D18: I2C | E18: =VLOOKUP(A18,'Z-Programme'!#REF!,1,FALSE) -> #REF!
A19: DEV-041 | B19: Nicht relevant | C19: MS-Entwicklungsphase 2 | D19: I2C | E19: =VLOOKUP(A19,'Z-Programme'!#REF!,1,FALSE) -> #REF!
A20: DEV-042 | B20: Nicht relevant | C20: Realize W1 | D20: I2C
A21: DEV-048 | B21: Nicht relevant | C21: Realize W1 | D21: R2R
A22: DEV-049 | B22: Nicht relevant | C22: Realize W1 | D22: R2R
A23: DEV-054 | B23: Nicht relevant | C23: Realize W1 | D23: R2R
A24: DEV-050 | B24: Nicht relevant | C24: Realize W1 | D24: I2C
A25: DEV-051 | B25: Nicht relevant | C25: Realize W1 | D25: I2C
A26: DEV-053 | B26: In Bearbeitung | C26: Realize W1 | D26: I2C | E26: =VLOOKUP(A26,'Z-Programme'!#REF!,1,FALSE) -> #REF!
A27: DEV-056 | B27: Fertig | C27: Realize W1 | D27: P2P
A28: DEV-057 | B28: Fertig | C28: Realize W1 | D28: P2P
A29: DEV-058 | B29: Fertig | C29: Realize W1 | D29: P2P
A30: DEV-059 | B30: Fertig | C30: Realize W1 | D30: P2P
A31: DEV-094 | B31: Nicht relevant | C31: MS-Entwicklungsphase 3 | D31: Tax
A32: DEV-095 | B32: Fertig | C32: Realize W1 | D32: P2P
A33: DEV-096 | B33: Fertig | C33: Realize W1 | D33: P2P
A34: DEV-061 | B34: Nicht relevant | C34: MS-Entwicklungsphase 3 | D34: S2P
A35: DEV-062 | B35: Nicht relevant | C35: MS-Entwicklungsphase 3 | D35: XX
A36: DEV-066 | B36: Nicht relevant | C36: MS-Entwicklungsphase 3 | D36: S2P
A37: DEV-067 | B37: In Bearbeitung | C37: Realize W1 | D37: S2P | E37: =VLOOKUP(A37,'Z-Programme'!#REF!,1,FALSE) -> #REF!
A38: DEV-068 | B38: In Bearbeitung | C38: Realize W1 | D38: I2C | E38: =VLOOKUP(A38,'Z-Programme'!#REF!,1,FALSE) -> #REF!
A39: DEV-070 | B39: In Bearbeitung | C39: Realize W1 | D39: S2P | E39: =VLOOKUP(A39,'Z-Programme'!#REF!,1,FALSE) -> #REF!
A40: DEV-072 | B40: In Bearbeitung | C40: Realize W1 | D40: S2P | E40: =VLOOKUP(A40,'Z-Programme'!#REF!,1,FALSE) -> #REF!
...

Sheet USR mit Z-Artefakt
A1: USR | B1: Z-Programm | C1: Match
A2: DEV-005 | B2: Nein | C2: =VLOOKUP(A2,'Z-Programme'!#REF!,1,FALSE) -> #REF!
A3: DEV-008 | B3: Nein | C3: =VLOOKUP(A3,'Z-Programme'!#REF!,1,FALSE) -> #REF!
A4: DEV-010 | B4: Ja | C4: =VLOOKUP(A4,'Z-Programme'!#REF!,1,FALSE) -> #REF!
A5: DEV-003 | B5: Nein | C5: =VLOOKUP(A5,'Z-Programme'!#REF!,1,FALSE) -> #REF!
A6: DEV-012 | B6: Ja | C6: =VLOOKUP(A6,'Z-Programme'!#REF!,1,FALSE) -> #REF!
A7: DEV-014 | B7: Nein | C7: =VLOOKUP(A7,'Z-Programme'!#REF!,1,FALSE) -> #REF!
A8: DEV-016 | B8: Nein | C8: =VLOOKUP(A8,'Z-Programme'!#REF!,1,FALSE) -> #REF!
A9: DEV-021 | B9: Nein | C9: =VLOOKUP(A9,'Z-Programme'!#REF!,1,FALSE) -> #REF!
A10: DEV-025 | B10: Ja | C10: =VLOOKUP(A10,'Z-Programme'!#REF!,1,FALSE) -> #REF!
A11: DEV-033 | B11: Ja | C11: =VLOOKUP(A11,'Z-Programme'!#REF!,1,FALSE) -> #REF!
A12: DEV-034 | B12: Ja | C12: =VLOOKUP(A12,'Z-Programme'!#REF!,1,FALSE) -> #REF!
A13: DEV-035 | B13: Ja | C13: =VLOOKUP(A13,'Z-Programme'!#REF!,1,FALSE) -> #REF!
... A120: DEV-053 | B120: Nein | C120: =VLOOKUP(A120,'Z-Programme'!#REF!,1,FALSE) -> #REF!
A121: DEV-053 | B121: Nein | C121: =VLOOKUP(A121,'Z-Programme'!#REF!,1,FALSE) -> #REF! | R121: Fracht
A122: DEV-053 | B122: Nein | C122: =VLOOKUP(A122,'Z-Programme'!#REF!,1,FALSE) -> #REF!
A123: DEV-053 | B123: Nein | C123: =VLOOKUP(A123,'Z-Programme'!#REF!,1,FALSE) -> #REF!
A124: DEV-053 | B124: Nein | C124: =VLOOKUP(A124,'Z-Programme'!#REF!,1,FALSE) -> #REF!
A125: DEV-053 | B125: Nein | C125: =VLOOKUP(A125,'Z-Programme'!#REF!,1,FALSE) -> #REF!
A126: DEV-053 | B126: Nein | C126: =VLOOKUP(A126,'Z-Programme'!#REF!,1,FALSE) -> #REF!
A127: DEV-053 | B127: Nein | C127: =VLOOKUP(A127,'Z-Programme'!#REF!,1,FALSE) -> #REF!
A128: DEV-053 | B128: Nein | C128: =VLOOKUP(A128,'Z-Programme'!#REF!,1,FALSE) -> #REF!
A129: DEV-053 | B129: Nein | C129: =VLOOKUP(A129,'Z-Programme'!#REF!,1,FALSE) -> #REF!
A130: DEV-053 | B130: Nein | C130: =VLOOKUP(A130,'Z-Programme'!#REF!,1,FALSE) -> #REF!
A131: DEV-079 | B131: Nein | C131: =VLOOKUP(A131,'Z-Programme'!#REF!,1,FALSE) -> #REF!
A132: DEV-156 | B132: Nein | C132: =VLOOKUP(A132,'Z-Programme'!#REF!,1,FALSE) -> #REF!
A133: DEV-157 | B133: Nein | C133: =VLOOKUP(A133,'Z-Programme'!#REF!,1,FALSE) -> #REF!
... A189: DEV-002 | B189: Ja | C189: =VLOOKUP(A189,'Z-Programme'!#REF!,1,FALSE) -> #REF!

Sheet sbbnv temp d010sinf
A1: 1 | B1: 2 | C1: 3 | D1: 4 | E1: 5 | F1: 6 | G1: 7 | H1: 8 | I1: 9 | J1: 10 | K1: 11 | L1: 12 | M1: 13 | N1: 14 | O1: 15 | P1: 16 | Q1: 17 | R1: 18 | S1: 19 | T1: 20
A2: PROG | B2: R3STATE | C2: SQLX | D2: EDTX | E2: DBNA | F2: CLAS | G2: TYPE | H2: OCCURS | I2: SUBC | J2: APPL | K2: SECU | L2: CNAM | M2: CDAT | N2: VERN | O2: LEVL | P2: RSTAT | Q2: RMAND | R2: RLOAD | S2: UNAM | U2: UDAT | V2: UTIME | W2: DATALG | X2: VARCL | Y2: DBAPL | Z2: FIXPT | AA2: SSET | AB2: SDATE | AC2: STIME | AD2: IDATE | AE2: ITIME | AF2: LDBNAME | AG2: UCCHECK | AH2: MAXLINELN
A3: ZFI_LAVA01 | B3: A | I3: 1 | J3: F | L3: ITTEXUI | M3: 45749 | N3: 000010 | P3: K | Q3: 100 | R3: DE | S3: ITTEXUI | T3: Irina Ultschenko | U3: 45925 | V3: 0.45231481 | W3: 57879 | X3: X | Z3: X | AB3: 45951 | AC3: 163835 | AD3: 45925 | AE3: 105120 | AG3: X | AH3: 0
A4: ZFI_SEPA_PRENOTE_INCL | B4: A | I4: I | J4: F | L4: ITTEXKA | M4: 45525 | N4: 000011 | P4: K | Q4: 100 | R4: DE | S4: ITTEXKA | T4: Alexander Krawietz | U4: 45525 | V4: 0.30334491 | W4: 4210 | X4: X | AB4: 45525 | AC4: 071649 | AD4: 45525 | AE4: 071649 | AG4: X | AH4: 0
A5: ZFI_SS_FB0100 | B5: A | I5: 1 | J5: F | L5: ITTEXRM | M5: 45756 | N5: 000028 | P5: K | Q5: 100 | R5: DE | S5: ITTEXRM | T5: Mayrina Rud | U5: 45945 | V5: 0.74018519 | W5: 44018 | X5: X | AB5: 45945 | AC5: 174552 | AD5: 45945 | AE5: 174552 | AG5: X | AH5: 0
A6: ZMV45AFZZ_SAVE_DOCUMENT_PREPAR | B6: A | I6: I | J6: V | L6: ITTEXRA | M6: 45706 | N6: 000033 | P6: K | Q6: 100 | R6: DE | S6: ITTEXRA | T6: Andreas Rustemeier | U6: 45749 | V6: 0.453125 | W6: 16569 | X6: X | AB6: 45749 | AC6: 105230 | AD6: 45749 | AE6: 105230 | AG6: X | AH6: 0
A7: ZSD_ADIN01_EXIT | B7: A | I7: I | J7: V | L7: ITTEXRM | M7: 45506 | N7: 000012 | P7: P | Q7: 100 | R7: DE | S7: ITTEXWR | T7: Rolf Winter | U7: 45796 | V7: 0.48186343 | W7: 33811 | X7: X | AB7: 45796 | AC7: 113353 | AD7: 45796 | AE7: 113353 | AG7: X | AH7: 0
A8: ZSD_MAR_BASIS | B8: A | I8: 1 | J8: V | L8: ITTEXRA | M8: 45602 | N8: 000029 | P8: K | Q8: 100 | R8: DE | S8: SBBNV | T8: Andreas Rustemeier | U8: 45901 | V8: 0.73578704 | W8: 59615 | X8: X | Z8: X | AB8: 45958 | AC8: 101336 | AD8: 45901 | AE8: 173932 | AG8: X | AH8: 0
A9: ZSD_MAR_BELEGHIS | B9: A | I9: 1 | J9: V | L9: ITTEXRA | M9: 45603 | N9: 000020 | P9: K | Q9: 100 | R9: DE | S9: ITTEXRA | T9: Andreas Rustemeier | U9: 45840 | V9: 0.66013889 | W9: 17674 | X9: X | Z9: X | AB9: 45947 | AC9: 145217 | AD9: 45840 | AE9: 155036 | AG9: X | AH9: 0
A10: ZSD_MAR_FI | B10: A | I10: 1 | J10: V | L10: ITTEXRA | M10: 45609 | N10: 000013 | P10: K | Q10: 100 | R10: DE | S10: ITTEXRA | T10: Andreas Rustemeier | U10: 45680 | V10: 0.42400463 | W10: 4483 | X10: X | Z10: X | AB10: 45947 | AC10: 145217 | AD10: 45680 | AE10: 101034 | AG10: X | AH10: 0
A11: ZXVVFU02 | B11: A | I11: I | J11: S | L11: ITTEXRA | M11: 45812 | N11: 000016 | P11: T | Q11: 100 | R11: DE | S11: ITTEXRA | T11: Andreas Rustemeier | U11: 45945 | V11: 0.67263889 | W11: 6358 | X11: X | AB11: 45945 | AC11: 160836 | AD11: 45945 | AE11: 160836 | AG11: X | AH11: 0

Sheet Z-EQA300
A2: Programm | B2: Report-Titel
A3: ZFI_RFBILA00 | B3: Bilanz/GuV
A4: ZMM_IVALUA_QUEUE_DISPLAY
A5: ZMM_IVALUA_QUEUE_PROCESS
A6: ZFI_ANZ_REISE_PBS | B6: Anzahl Reisen für interne Leistungsverrechnung
A7: ZFI_SAPF150D2 | B7: FI Mahnen - Druckprogramm
A8: ZFI_EXCEL_UPLOAD | B8: Programm ZFI_EXCEL_UPLOAD
A9: ZFI_INKO00 | B9: Übergabe Inkassounternehmen - Mahndaten säumiger Zahler
A10: ZFI_INKO00_EOS | B10: EOS : Übergabe mit neuer Struktur
A11: ZFI_INKO03 | B11: Rückmeldeverarbeitung der Aktenzeichen
A12: ZFI_INKO03_EOS | B12: Rückmeldeverarbeitung der Inkassonummer
A13: ZFI_INKO04 | B13: BI: Rückmeldung Aktenzeichen: Update Debitoren Stammsatz
A14: ZFI_INKO04_EOS | B14: BI: Rückmeldung Aktenzeichen: Update Debitoren Stammsatz
A15: ZFI_INKO05 | B15: BI: belegen Segmenttext mit Aktenkennzeichen
A16: ZFI_INKO05_EOS | B16: BI: belegen Segmenttext mit Aktenkennzeichen
A17: ZFI_UPDATE_COCKPIT_ZAHLUNG | B17: Aktualisierung Tabelle ZFI_INKO_COCKPIT,ZFI_INKO_COCKPI2 für Zahlung
... A147: ZFI_ELSY_SCHNITTSTELLE | B147: Rechnungen Telekom Datenverkehr (ELSY) Konvertierung Inhouseformat
A148: Z_ACAC_D_TRANS_EXAMPLE_S4_TOP
A149: ZACAC_DATA_TRANSFER | B149: Übernahme von Debitoren-/Kreditorenrechnungen in die Accrual Engine
A150: ZFI_MONATSABSCHLUSS_UPLOAD | B150: Programm ZFI_MONATSABSCHLUSS_UPLOAD
A151: Z_ACAC_D_TRANS_EXAMPLE_S4 | B151: Übernahme von Debitoren-/Kreditorenrechnungen in die Accrual Engine
A152: ZBC_TAB_EXPIMP2 | B152: ZBC_TAB_EXPIMP2 Tabellen Impotieren, DS-Filtern, Werte-Umschlüsseln
A153: ZBC_TAB_EXPIMP2_SIK | B153: ZBC_TAB_EXPIMP2 Tabellen Impotieren, DS-Filtern ## Sicherung ###
A154: ZFI_AVM_VERSICHERUNG | B154: Umbuchung Zahlungseingänge für Versicherungsfälle Autovermietung
A155: ZFI_SAM_VBR_LISTE | B155: Sanktionsprüfung: Auswertung für Versicherungen (VBR)
A156: ZADAC_CLASSIC_TR_LAVA_EXP | B156: LAVA FX-Export
A157: ZFI_SD_UM | B157: Umbuchungen von Erlösbuchungen
A158: ZFI_SS_FB0100 | B158: Standardschnittstelle für Belegerfassung und Stammsatzpflege
A159: ZHR_CONCUR_RESET_POSTING | B159: Concur - gebuchte Expense Reports für erneute Buchung zurücksetzen
A160: ZFI_BARCO_DEL | B160: Barcodes löschen
... A211: ZFI_FILE_FOR_ABSTIMMTOOL | B211: Datei für Abstimmtool erzeugen

Sheet Tabelle1
B2: Welle 1 | C2: Welle 2 | D2: Welle 3 ff
B3: Ja | D3: Ja Ergebnis | E3: (Leer) | Q3: (Leer) Ergebnis | R3: Gesamtergebnis
B4: (Leer) | C4: (Leer) Ergebnis | E4: ? | F4: ? Ergebnis | G4: Ja | H4: Ja Ergebnis | I4: Nein | K4: Nein Ergebnis | L4: Nein | M4: Nein Ergebnis | N4: (Leer) | P4: (Leer) Ergebnis
B5: (Leer) | E5: ? | G5: Nein | I5: ? | J5: Ja | L5: Ja | N5: x | O5: (Leer)
A6: Anzahl von Z-Programm R/3 (insgesamt 654) | B6: 198 | C6: 198 | D6: 198 | E6: 29 | F6: 29 | G6: 20 | H6: 20 | I6: 38 | J6: 14 | K6: 52 | L6: 3 | M6: 3 | N6: 30 | O6: 328 | P6: 358 | Q6: 462 | R6: 660

Sheet Tabelle2
A2: Übernahme in S/4 geplant | B2: Anzahl von Übernahme in S/4 geplant
A3: Nein | B3: 328
A4: Ja | B4: 265
A5: Offen | B5: 67
A6: Gesamtergebnis | B6: 660

Sheet Z-Programme (2)
A1: Z-Programm R/3 (insgesamt 654) | B1: vorhanden EQA | C1: Übernahme in S/4 geplant | D1: USR CALM | E1: Welle 1 | F1: Welle 2 | G1: Welle 3 ff | H1: Coding Zahlwege | I1: Klärung durch | J1: Beschreibung
A2: Z_CLEAN_EVTTAB | B2: Nein | C2: Nein | J2: Hilfsprogramm zur Bereinigung Inkonsistenzen in Jobtabelle BTCEVTJOB
A3: Z_IDOC_STATUS_SET | B3: Nein | C3: Ja | F3: Nein | G3: Ja | J3: Idoc Status auf erledigt setzen (nur BuKrs 1000)
A4: Z_INFO_PRICING_SERVICES_USER | B4: Nein | C4: Nein | J4: Z_INFO_PRICING_SERVICES_USER lt. SAP Hinweis 1786263
A5: Z_REPAIR_ADRNR_1 | B5: Nein | C5: Nein | J5: Reparatur der Adressinkonsistenz in Tabelle VBPA und KNA1
A6: Z_SAPMZSWA | B6: Nein | C6: Ja | F6: Nein | G6: Ja | J6: Programm SAPMZSWA - Batterieservice
A7: Z_SAPMZSWA_MENUE | B7: Nein | C7: Ja | F7: Nein | G7: Ja | J7: Menü Batterieservice
A8: Z_SAPMZSWAT | B8: Nein | C8: Ja | F8: Nein | G8: Ja | J8: Modulpool: Elektronisches Bezahlen SWA-Terminal (Straßenwacht)
A9: Z0SAP_12 | B9: Nein | C9: Nein | J9: Datendatei-View: Geplante Abschreibungen auf Anlagen
A10: ZAA_ANLAGENTR_COPY_LANGTEXT | B10: Nein | C10: Nein | J10: Anlagentransfer Langtexte kopieren
A11: ZAA_ANLAGENTRANSFER | B11: Nein | C11: Nein | J11: Anlagentransfer
A12: ZAA_CO_KONTIERUNG | B12: Nein | C12: Nein | J12: Änderung von Innenaufträgen/Kostenstellen in Anlagen
A13: ZAA_INVE01 | B13: Nein | C13: Nein | J13: Inventurliste nach Anlagennummern / Anlagentext
A14: ZAA_INVE06 | B14: Nein | C14: Nein | J14: Inventurliste nach Anlagennummern / Anlagentext
A15: ZAA_INVE07 | B15: Nein | C15: Nein | J15: Inventurliste nach Kostenrechnungsobjekten
A16: ZAA_MASS_DOWN | B16: Nein | C16: Nein | D16: DEV-002 | J16: Anlagenstamm Massenänderung: Download
A17: ZAA_MASS_UP | B17: Nein | C17: Nein | D17: DEV-002 | J17: Massenänderung Anlagenstamm: Upload CSV-Datei
A18: ZAA_RAHIST01 | B18: Nein | C18: Nein | J18: Anlagenhistorie
A19: ZAA_RAPOST2010 | B19: Nein | C19: Nein | J19: Buchen der Abschreibungen
A20: ZAA_STAMMDAT_ALV | B20: Nein | C20: Nein | D20: DEV-002 | J20: Stammdaten-Auswertung ALV-Liste ( mehrzeilig )
A21: ZACAC_DATA_TRANSFER | B21: Ja | C21: Ja | D21: DEV-150 | E21: Ja | J21: Übernahme von Debitoren-/Kreditorenrechnungen in die Accrual Engine
A22: ZACAC_DSITEMS | B22: Nein | C22: Nein | J22: Anzeigen von Abgrenzungsobjekten + kd.eigene Parameter
A23: ZBC_ADDR_CHECK | B23: Nein | C23: Nein | J23: Reparaturprogramm: Prüfen Debitoren auf fehlende Adresse-Einträge in Archivierung
A24: ZBC_AL_REORG_OUT | B24: Nein | C24: Ja | F24: Ja | G24: Nein | J24: Archivelink Reorganisation - Erstellen Löschdatei und Tabelle für's Löschen von Sätzen in den Verknüpfungstabellen
A25: ZBC_AL_REORG_RETURN | B25: Nein | C25: Ja | F25: Ja | G25: Nein | J25: Archivelink Reorganisation - Rückantwort NE-Databridge
A26: ZBC_AL_REORG_VTABS | B26: Nein | C26: Ja | F26: Ja | G26: Nein | J26: Archivelink Reorganisation - Pflege der Verknüpfungstabellen
A27: ZBC_ANONYM_ZQ1 | B27: Nein | C27: Ja | F27: Ja | G27: Nein | J27: Anonymisierungstool in Q Systemen
A28: ZBC_BDCLOG_ALV | B28: Nein | C28: Ja | F28: Ja | G28: Nein | J28: Archivierte BDC Mappenprotokolle anzeigen
A29: ZBC_BDCLOG_ARCHIVE | B29: Nein | C29: Ja | F29: Ja | G29: Nein | J29: BDC Mappenprotokolle archivieren
A30: ZBC_BDCLOG_ARCHIVE_FIX | B30: Nein | C30: Ja | F30: Ja | G30: Nein | J30: BDC Mappenprotokolle archiv Objekte importieren
A31: ZBC_BELEG_VOLUME | B31: Nein | C31: Nein | J31: Ermittlung von Beleganzahl / -wert je Buchungskreis als Basis für Verteilschlüssel SAP Systempreis Verteilung
A32: ZBC_CALL_PROCEDURE | B32: Nein | C32: Nein | J32: Aufruf einer "Stored Procedure" in der Berichtswesendatenbank
A33: ZBC_CHECK_NRIV | B33: Nein | C33: Ja | F33: Ja | G33: Nein | J33: mit diesem Programm können Nummernkreise auf Fehler geprüft werden und freie Intervalle ermittelt werden.
A34: ZBC_COPY_DATASET | B34: Nein | C34: Ja | F34: Ja | G34: Nein | J34: Wird benötigt für ELMO für Dateiaufstellung für Netz HG105C. Es ist eine Kopie von ZFI_COPY_TEXT_DATASET ergänzt mit Archivierungsfunktionalität
A35: ZBC_EVENT_RAISE | B35: Ja | C35: Ja | E35: Ja | J35: Auslösen eines Kundenereignisses
A36: ZBC_EXCELTABUPLOAD | B36: Nein | C36: Nein | J36: Generischer Upload von Excel-Tabellen in R/3-Tabellen
A37: ZBC_F110_JOBCTRL | B37: Nein | C37: Offen | F37: ? | G37: ? | I37: J. Schaut | J37: Zahllauf Folgeverarbeitungssteuerung
A38: ZBC_F110_SPOOL_UPDATE | B38: Nein | C38: Offen | F38: ? | G38: ? | I38: J. Schaut | J38: Update von Spool-Datasets (Zahllaufversion)
A39: ZBC_FILE_DELETE | B39: Ja | C39: Ja | E39: Ja | J39: Dateienlöschung über Report ZBC_FILE_DELETE
A40: ZBC_FILE_EVENT_RAISE | B40: Ja | C40: Ja | E40: Ja | J40: Dateieneventauslösung
...

Sheet Tabelle5
A1: Welle 1 | B1: (Alle)
A2: Welle 2 | B2: (Alle)
A3: Welle 3 ff | B3: (Alle)
B5: Übernahme in S/4 geplant
B6: Ja | C6: Nein | D6: Offen | E6: Gesamtergebnis
A7: Anzahl von Z-Programm R/3 (insgesamt 654) | B7: 265 | C7: 328 | D7: 67 | E7: 660
